<?xml version="1.0" encoding="utf-8"?>
<!-- This URDF was automatically created by SolidWorks to URDF Exporter! Originally created by Stephen Brawner (brawner@gmail.com) 
     Commit Version: 1.5.1-0-g916b5db  Build Version: 1.5.7152.31018
     For more information, please see http://wiki.ros.org/sw_urdf_exporter -->
<robot
  name="model20">
  <link
    name="base_link">
    <inertial>
      <origin
        xyz="-0.0925505753581464 0.0774378875267919 0.0428958855617279"
        rpy="0 0 0" />
      <mass
        value="3.22961622771048" />
      <inertia
        ixx="0.00580312787317249"
        ixy="1.93643410745568E-06"
        ixz="7.56620702229478E-07"
        iyy="0.00722042643267808"
        iyz="3.86677335720296E-07"
        izz="0.0125136556433196" />
    </inertial>
    <visual>
      <origin
        xyz="0 0 0"
        rpy="0 0 0" />
      <geometry>
        <mesh
          filename="package://model20/meshes/base_link.STL" />
      </geometry>
      <material
        name="">
        <color
          rgba="0.752941176470588 0.752941176470588 0.752941176470588 1" />
      </material>
    </visual>
    <collision>
      <origin
        xyz="0 0 0"
        rpy="0 0 0" />
      <geometry>
        <mesh
          filename="package://model20/meshes/base_link.STL" />
      </geometry>
    </collision>
  </link>
  <link
    name="left_front_wheel_suspension">
    <inertial>
      <origin
        xyz="-0.00786753377996494 -0.0155948984609842 0.0232556468762561"
        rpy="0 0 0" />
      <mass
        value="0.0651133753252895" />
      <inertia
        ixx="1.48802654908116E-05"
        ixy="1.64845451975805E-08"
        ixz="-1.56420031463122E-07"
        iyy="1.75245555055195E-05"
        iyz="-2.96403540336108E-09"
        izz="8.01010024686586E-06" />
    </inertial>
    <visual>
      <origin
        xyz="0 0 0"
        rpy="0 0 0" />
      <geometry>
        <mesh
          filename="package://model20/meshes/left_front_wheel_suspension.STL" />
      </geometry>
      <material
        name="">
        <color
          rgba="0.752941176470588 0.752941176470588 0.752941176470588 1" />
      </material>
    </visual>
    <collision>
      <origin
        xyz="0 0 0"
        rpy="0 0 0" />
      <geometry>
        <mesh
          filename="package://model20/meshes/left_front_wheel_suspension.STL" />
      </geometry>
    </collision>
  </link>
  <joint
    name="left_front_wheel_suspension_joint"
    type="prismatic">
    <origin
      xyz="-0.019999 0.15549 -0.030998"
      rpy="1.5708 0 -1.5708" />
    <parent
      link="base_link" />
    <child
      link="left_front_wheel_suspension" />
    <axis
      xyz="0 1 0" />
    <limit
      lower="0"
      upper="0"
      effort="0"
      velocity="0" />
  </joint>
  <link
    name="left_front_wheel">
    <inertial>
      <origin
        xyz="0.0158399891826274 -4.59981459866032E-09 7.99690621500204E-08"
        rpy="0 0 0" />
      <mass
        value="0.22822169800504" />
      <inertia
        ixx="0.000789211576324214"
        ixy="-1.09995507949862E-10"
        ixz="1.91230261060087E-09"
        iyy="0.000410429434291453"
        iyz="-5.55677330321344E-16"
        izz="0.000410429434301075" />
    </inertial>
    <visual>
      <origin
        xyz="0 0 0"
        rpy="0 0 0" />
      <geometry>
        <mesh
          filename="package://model20/meshes/left_front_wheel.STL" />
      </geometry>
      <material
        name="">
        <color
          rgba="1 1 1 1" />
      </material>
    </visual>
    <collision>
      <origin
        xyz="0 0 0"
        rpy="0 0 0" />
      <geometry>
        <mesh
          filename="package://model20/meshes/left_front_wheel.STL" />
      </geometry>
    </collision>
  </link>
  <joint
    name="left_front_wheel_joint"
    type="continuous">
    <origin
      xyz="-0.01976 -0.021787 0.0099999"
      rpy="3.0841 0 3.1416" />
    <parent
      link="left_front_wheel_suspension" />
    <child
      link="left_front_wheel" />
    <axis
      xyz="1 0 0" />
    <limit
      effort="3.1"
      velocity="7" />
  </joint>
  <link
    name="right_front_wheel_suspension">
    <inertial>
      <origin
        xyz="-0.00415434378457435 -0.0156302499401892 0.0232556866612721"
        rpy="0 0 0" />
      <mass
        value="0.0651133753251555" />
      <inertia
        ixx="1.48802639086072E-05"
        ixy="1.64845302056301E-08"
        ixz="1.56454773175217E-07"
        iyy="1.75245555054544E-05"
        iyz="2.9641187651021E-09"
        izz="8.01010182899686E-06" />
    </inertial>
    <visual>
      <origin
        xyz="0 0 0"
        rpy="0 0 0" />
      <geometry>
        <mesh
          filename="package://model20/meshes/right_front_wheel_suspension.STL" />
      </geometry>
      <material
        name="">
        <color
          rgba="0.752941176470588 0.752941176470588 0.752941176470588 1" />
      </material>
    </visual>
    <collision>
      <origin
        xyz="0 0 0"
        rpy="0 0 0" />
      <geometry>
        <mesh
          filename="package://model20/meshes/right_front_wheel_suspension.STL" />
      </geometry>
    </collision>
  </link>
  <joint
    name="right_front_wheel_suspension_joint"
    type="prismatic">
    <origin
      xyz="-0.019999 -0.014509 -0.030998"
      rpy="1.5708 0 -1.5708" />
    <parent
      link="base_link" />
    <child
      link="right_front_wheel_suspension" />
    <axis
      xyz="0 1 0" />
    <limit
      lower="0"
      upper="0"
      effort="0"
      velocity="0" />
  </joint>
  <link
    name="right_front_wheel">
    <inertial>
      <origin
        xyz="0.015839199018542 1.11022302462516E-16 0"
        rpy="0 0 0" />
      <mass
        value="0.22822169800504" />
      <inertia
        ixx="0.000789211576333899"
        ixy="-3.39931873462569E-20"
        ixz="5.22971288940966E-21"
        iyy="0.000410429434291421"
        iyz="-3.86247023947961E-19"
        izz="0.000410429434291419" />
    </inertial>
    <visual>
      <origin
        xyz="0 0 0"
        rpy="0 0 0" />
      <geometry>
        <mesh
          filename="package://model20/meshes/right_front_wheel.STL" />
      </geometry>
      <material
        name="">
        <color
          rgba="1 1 1 1" />
      </material>
    </visual>
    <collision>
      <origin
        xyz="0 0 0"
        rpy="0 0 0" />
      <geometry>
        <mesh
          filename="package://model20/meshes/right_front_wheel.STL" />
      </geometry>
    </collision>
  </link>
  <joint
    name="right_front_wheel_joint"
    type="continuous">
    <origin
      xyz="0.0077391 -0.021785 0.01"
      rpy="0.1626 0 0" />
    <parent
      link="right_front_wheel_suspension" />
    <child
      link="right_front_wheel" />
    <axis
      xyz="1 0 0" />
    <limit
      effort="3.1"
      velocity="7" />
  </joint>
  <link
    name="camera">
    <inertial>
      <origin
        xyz="0.000445525429401739 -1.1063488044194E-05 0.00129821842499728"
        rpy="0 0 0" />
      <mass
        value="0.0436119955028422" />
      <inertia
        ixx="2.35707059694687E-05"
        ixy="-1.01847086177712E-09"
        ixz="2.17583930111272E-08"
        iyy="4.29479039927907E-06"
        iyz="-8.85046657821771E-10"
        izz="2.21058152194316E-05" />
    </inertial>
    <visual>
      <origin
        xyz="0 0 0"
        rpy="0 0 0" />
      <geometry>
        <mesh
          filename="package://model20/meshes/camera.STL" />
      </geometry>
      <material
        name="">
        <color
          rgba="0.792156862745098 0.819607843137255 0.933333333333333 1" />
      </material>
    </visual>
    <collision>
      <origin
        xyz="0 0 0"
        rpy="0 0 0" />
      <geometry>
        <mesh
          filename="package://model20/meshes/camera.STL" />
      </geometry>
    </collision>
  </link>
  <joint
    name="camera"
    type="fixed">
    <origin
      xyz="0.0043645 0.076511 0.089"
      rpy="0 0.40143 0" />
    <parent
      link="base_link" />
    <child
      link="camera" />
    <axis
      xyz="0 0 0" />
  </joint>
  <link
    name="camera2">
    <inertial>
      <origin
        xyz="0.000445525266833613 -1.10639236487325E-05 0.00129821764747488"
        rpy="0 0 0" />
      <mass
        value="0.0436119958611832" />
      <inertia
        ixx="2.35707063464805E-05"
        ixy="-1.01836626404882E-09"
        ixz="2.17587007085046E-08"
        iyy="4.29479063311557E-06"
        iyz="-8.85041666160268E-10"
        izz="2.21058153836914E-05" />
    </inertial>
    <visual>
      <origin
        xyz="0 0 0"
        rpy="0 0 0" />
      <geometry>
        <mesh
          filename="package://model20/meshes/camera2.STL" />
      </geometry>
      <material
        name="">
        <color
          rgba="0.792156862745098 0.819607843137255 0.933333333333333 1" />
      </material>
    </visual>
    <collision>
      <origin
        xyz="0 0 0"
        rpy="0 0 0" />
      <geometry>
        <mesh
          filename="package://model20/meshes/camera2.STL" />
      </geometry>
    </collision>
  </link>
  <joint
    name="camera2"
    type="fixed">
    <origin
      xyz="0.00072751 0.076511 0.15475"
      rpy="0 0.17453 0" />
    <parent
      link="base_link" />
    <child
      link="camera2" />
    <axis
      xyz="0 0 0" />
  </joint>
  <link
    name="lidar">
    <inertial>
      <origin
        xyz="-0.00868778989367713 -0.00242014065569161 -0.0287648859064543"
        rpy="0 0 0" />
      <mass
        value="0.0730845706123876" />
      <inertia
        ixx="1.9580875609635E-05"
        ixy="-1.03933750344926E-07"
        ixz="4.28391241039135E-07"
        iyy="2.41250086763081E-05"
        iyz="-9.42709906914264E-09"
        izz="4.1418452244397E-05" />
    </inertial>
    <visual>
      <origin
        xyz="0 0 0"
        rpy="0 0 0" />
      <geometry>
        <mesh
          filename="package://model20/meshes/lidar.STL" />
      </geometry>
      <material
        name="">
        <color
          rgba="0.792156862745098 0.819607843137255 0.933333333333333 1" />
      </material>
    </visual>
    <collision>
      <origin
        xyz="0 0 0"
        rpy="0 0 0" />
      <geometry>
        <mesh
          filename="package://model20/meshes/lidar.STL" />
      </geometry>
    </collision>
  </link>
  <joint
    name="lidar_joint"
    type="fixed">
    <origin
      xyz="-0.064259 0.068705 0.2235"
      rpy="0 0 0" />
    <parent
      link="base_link" />
    <child
      link="lidar" />
    <axis
      xyz="0 0 0" />
  </joint>
  <link
    name="imu">
    <inertial>
      <origin
        xyz="0 0 0.00250000000000003"
        rpy="0 0 0" />
      <mass
        value="0.000510000000000001" />
      <inertia
        ixx="5.31250000000002E-09"
        ixy="-7.37257477290141E-26"
        ixz="-1.63867682737907E-40"
        iyy="5.31250000000002E-09"
        iyz="-5.52943107967612E-26"
        izz="8.50000000000004E-09" />
    </inertial>
    <visual>
      <origin
        xyz="0 0 0"
        rpy="0 0 0" />
      <geometry>
        <mesh
          filename="package://model20/meshes/imu.STL" />
      </geometry>
      <material
        name="">
        <color
          rgba="1 1 1 1" />
      </material>
    </visual>
    <collision>
      <origin
        xyz="0 0 0"
        rpy="0 0 0" />
      <geometry>
        <mesh
          filename="package://model20/meshes/imu.STL" />
      </geometry>
    </collision>
  </link>
  <joint
    name="imu"
    type="fixed">
    <origin
      xyz="-0.095 0.11775 0.17"
      rpy="0 0 0" />
    <parent
      link="base_link" />
    <child
      link="imu" />
    <axis
      xyz="0 0 0" />
  </joint>
  <link
    name="left_rear_wheel_suspension">
    <inertial>
      <origin
        xyz="0 -0.005 1.11022302462516E-16"
        rpy="0 0 0" />
      <mass
        value="0.00774637194071073" />
      <inertia
        ixx="3.9707044697232E-07"
        ixy="-2.59626609761759E-23"
        ixz="1.7265241970474E-23"
        iyy="6.65034694932794E-07"
        iyz="-4.68375338513748E-24"
        izz="3.97070446972319E-07" />
    </inertial>
    <visual>
      <origin
        xyz="0 0 0"
        rpy="0 0 0" />
      <geometry>
        <mesh
          filename="package://model20/meshes/left_rear_wheel_suspension.STL" />
      </geometry>
      <material
        name="">
        <color
          rgba="0.898039215686275 0.917647058823529 0.929411764705882 1" />
      </material>
    </visual>
    <collision>
      <origin
        xyz="0 0 0"
        rpy="0 0 0" />
      <geometry>
        <mesh
          filename="package://model20/meshes/left_rear_wheel_suspension.STL" />
      </geometry>
    </collision>
  </link>
  <joint
    name="left_rear_wheel_suspension_joint"
    type="continuous">
    <origin
      xyz="-0.293 0.1615 -0.030998"
      rpy="1.5708 0 -1.5708" />
    <parent
      link="base_link" />
    <child
      link="left_rear_wheel_suspension" />
    <axis
      xyz="0 1 0" />
  </joint>
  <link
    name="left_rear_wheel">
    <inertial>
      <origin
        xyz="0 -0.0404395006329032 0"
        rpy="0 0 0" />
      <mass
        value="0.342512288692214" />
      <inertia
        ixx="0.000165711359519627"
        ixy="9.81734839423475E-22"
        ixz="6.2469123454979E-21"
        iyy="0.00011406556894596"
        iyz="3.87223575174732E-21"
        izz="0.000165711359519627" />
    </inertial>
    <visual>
      <origin
        xyz="0 0 0"
        rpy="0 0 0" />
      <geometry>
        <mesh
          filename="package://model20/meshes/left_rear_wheel.STL" />
      </geometry>
      <material
        name="">
        <color
          rgba="0.898039215686275 0.917647058823529 0.929411764705882 1" />
      </material>
    </visual>
    <collision>
      <origin
        xyz="0 0 0"
        rpy="0 0 0" />
      <geometry>
        <mesh
          filename="package://model20/meshes/left_rear_wheel.STL" />
      </geometry>
    </collision>
  </link>
  <joint
    name="left_rear_wheel_joint"
    type="fixed">
    <origin
      xyz="0 -0.019516 0"
      rpy="0 0 0" />
    <parent
      link="left_rear_wheel_suspension" />
    <child
      link="left_rear_wheel" />
    <axis
      xyz="0 0 0" />
  </joint>
  <link
    name="right_rear_wheel_suspension">
    <inertial>
      <origin
        xyz="0 -0.005 -1.11022302462516E-16"
        rpy="0 0 0" />
      <mass
        value="0.00774637194071073" />
      <inertia
        ixx="3.9707044697232E-07"
        ixy="-2.59626609761758E-23"
        ixz="5.84249445698131E-24"
        iyy="6.65034694932794E-07"
        iyz="-4.68375338513718E-24"
        izz="3.97070446972319E-07" />
    </inertial>
    <visual>
      <origin
        xyz="0 0 0"
        rpy="0 0 0" />
      <geometry>
        <mesh
          filename="package://model20/meshes/right_rear_wheel_suspension.STL" />
      </geometry>
      <material
        name="">
        <color
          rgba="0.898039215686275 0.917647058823529 0.929411764705882 1" />
      </material>
    </visual>
    <collision>
      <origin
        xyz="0 0 0"
        rpy="0 0 0" />
      <geometry>
        <mesh
          filename="package://model20/meshes/right_rear_wheel_suspension.STL" />
      </geometry>
    </collision>
  </link>
  <joint
    name="right_rear_wheel_suspension_joint"
    type="continuous">
    <origin
      xyz="-0.293 -0.0084978 -0.030998"
      rpy="1.5708 0 -1.5708" />
    <parent
      link="base_link" />
    <child
      link="right_rear_wheel_suspension" />
    <axis
      xyz="0 1 0" />
  </joint>
  <link
    name="right_rear_wheel">
    <inertial>
      <origin
        xyz="0 -0.0404395006329033 0"
        rpy="0 0 0" />
      <mass
        value="0.342512288692214" />
      <inertia
        ixx="0.000165711359519628"
        ixy="-5.41262773559375E-22"
        ixz="4.24561514707314E-21"
        iyy="0.00011406556894596"
        iyz="2.94451414291141E-21"
        izz="0.000165711359519628" />
    </inertial>
    <visual>
      <origin
        xyz="0 0 0"
        rpy="0 0 0" />
      <geometry>
        <mesh
          filename="package://model20/meshes/right_rear_wheel.STL" />
      </geometry>
      <material
        name="">
        <color
          rgba="0.898039215686275 0.917647058823529 0.929411764705882 1" />
      </material>
    </visual>
    <collision>
      <origin
        xyz="0 0 0"
        rpy="0 0 0" />
      <geometry>
        <mesh
          filename="package://model20/meshes/right_rear_wheel.STL" />
      </geometry>
    </collision>
  </link>
  <joint
    name="right_rear_wheel_joint"
    type="fixed">
    <origin
      xyz="0 -0.019516 0"
      rpy="0 0 0" />
    <parent
      link="right_rear_wheel_suspension" />
    <child
      link="right_rear_wheel" />
    <axis
      xyz="0 0 0" />
  </joint>


<transmission name="wheel_front_left_transmission">
<type>transmission_interface/SimpleTransmission</type>
<joint name="left_front_wheel_joint">
  <hardwareInterface>hardware_interface/EffortJointInterface</hardwareInterface>
</joint>
<actuator name="wheel_front_left_motor">
  <hardwareInterface>hardware_interface/EffortJointInterface</hardwareInterface>
  <mechanicalReduction>1</mechanicalReduction>
</actuator>
</transmission>

<transmission name="wheel_front_right_transmission">
  <type>transmission_interface/SimpleTransmission</type>
  <joint name="right_front_wheel_joint">
    <hardwareInterface>hardware_interface/EffortJointInterface</hardwareInterface>
  </joint>
  <actuator name="wheel_front_right_motor">
    <hardwareInterface>hardware_interface/EffortJointInterface</hardwareInterface>
    <mechanicalReduction>1</mechanicalReduction>
  </actuator>
</transmission>

<transmission name="left_front_wheel_suspension_transmission">
    <type>transmission_interface/SimpleTransmission</type>
    <joint name="left_front_wheel_suspension_joint">
      <hardwareInterface>hardware_interface/EffortJointInterface</hardwareInterface>
    </joint>
    <actuator name="left_suspension_actuator">
      <hardwareInterface>hardware_interface/EffortJointInterface</hardwareInterface>
      <mechanicalReduction>1</mechanicalReduction>
    </actuator>
  </transmission>

  <transmission name="left_rear_wheel_suspension_transmission">
      <type>transmission_interface/SimpleTransmission</type>
      <joint name="left_rear_wheel_suspension_joint">
        <hardwareInterface>hardware_interface/EffortJointInterface</hardwareInterface>
      </joint>
      <actuator name="left_suspension_actuator">
        <hardwareInterface>hardware_interface/EffortJointInterface</hardwareInterface>
        <mechanicalReduction>1</mechanicalReduction>
      </actuator>
    </transmission>

    <transmission name="right_front_wheel_suspension_transmission">
      <type>transmission_interface/SimpleTransmission</type>
      <joint name="right_front_wheel_suspension_joint">
        <hardwareInterface>hardware_interface/EffortJointInterface</hardwareInterface>
      </joint>
      <actuator name="right_suspension_actuator">
        <hardwareInterface>hardware_interface/EffortJointInterface</hardwareInterface>
        <mechanicalReduction>1</mechanicalReduction>
      </actuator>
    </transmission>

    <transmission name="right_rear_wheel_suspension_transmission">
      <type>transmission_interface/SimpleTransmission</type>
      <joint name="right_rear_wheel_suspension_joint">
        <hardwareInterface>hardware_interface/EffortJointInterface</hardwareInterface>
      </joint>
      <actuator name="right_suspension_actuator">
        <hardwareInterface>hardware_interface/EffortJointInterface</hardwareInterface>
        <mechanicalReduction>1</mechanicalReduction>
      </actuator>
    </transmission>

    <gazebo>
     <plugin name="gazebo_ros_control" filename="libgazebo_ros_control.so">
       <robotNamespace>/model20</robotNamespace>
       <robotSimType>gazebo_ros_control/DefaultRobotHWSim</robotSimType>
     </plugin>
   </gazebo>
  <gazebo reference="base_link">
     <mu1>1.0</mu1>
     <mu2>1.0</mu2>
     <material>Gazebo/Orange</material>
   </gazebo>

   <gazebo reference="left_front_wheel">
       <mu1>1.0</mu1>
       <mu2>1.0</mu2>
       <fdir1>1 0 0</fdir1>
       <material>Gazebo/FlatBlack</material>
     </gazebo>

     <gazebo reference="right_front_wheel">
        <mu1>1.0</mu1>
       <mu2>1.0</mu2>
       <fdir1>1 0 0</fdir1>
       <material>Gazebo/FlatBlack</material>
     </gazebo>

   <gazebo reference="left_rear_wheel">
        <mu1>1.0</mu1>
       <mu2>1.0</mu2>
       <fdir1>1 0 0</fdir1>
       <material>Gazebo/FlatBlack</material>
     </gazebo>

     <gazebo reference="right_rear_wheel">
       <mu1>1.0</mu1>
       <mu2>1.0</mu2>
       <fdir1>1 0 0</fdir1>
       <material>Gazebo/FlatBlack</material>
     </gazebo>

     <gazebo reference="left_front_wheel_suspension">
       <mu1>0.2</mu1>
       <mu2>0.2</mu2>
       <kd>50000.0</kd>
       <kp>10.0</kp>
       <material>Gazebo/Red</material>
     </gazebo>
     <gazebo reference="right_front_wheel_suspension">
       <mu1>0.2</mu1>
       <mu2>0.2</mu2>
       <kd>50000.0</kd>
       <kp>10.0</kp>
       <material>Gazebo/Red</material>
     </gazebo>
      <gazebo reference="left_rear_wheel_suspension">
       <mu1>0.2</mu1>
       <mu2>0.2</mu2>
       <kd>50000.0</kd>
       <kp>10.0</kp>
       <material>Gazebo/Red</material>
     </gazebo>
     <gazebo reference="right_rear_wheel_suspension">
       <mu1>0.2</mu1>
       <mu2>0.2</mu2>
       <kd>50000.0</kd>
       <kp>10.0</kp>
       <material>Gazebo/Red</material>
     </gazebo>

     <gazebo reference="camera">
       <material>Gazebo/FlatBlack</material>
     </gazebo>

     <gazebo reference="camera2">
       <material>Gazebo/Blue</material>
     </gazebo>

     <gazebo reference="camera">
       <sensor type="depth" name="realsense_R200">
         <always_on>true</always_on>
         <visualize>$(arg camera_visual)</visualize>
         <camera>
             <horizontal_fov>1.3439</horizontal_fov>
             <image>
                 <width>1920</width>
                 <height>1080</height>
                 <format>R8G8B8</format>
             </image>
             <depth_camera></depth_camera>
             <clip>
                 <near>0.03</near>
                 <far>100</far>
             </clip>
         </camera>
         <plugin name="camera_controller" filename="libgazebo_ros_openni_kinect.so">
           <baseline>0.2</baseline>
           <alwaysOn>true</alwaysOn>
           <updateRate>30.0</updateRate>
           <cameraName>camera</cameraName>
           <frameName>camera_rgb_optical_frame</frameName>
           <imageTopicName>rgb/image_raw</imageTopicName>
           <depthImageTopicName>depth/image_raw</depthImageTopicName>
           <pointCloudTopicName>depth/points</pointCloudTopicName>
           <cameraInfoTopicName>rgb/camera_info</cameraInfoTopicName>
           <depthImageCameraInfoTopicName>depth/camera_info</depthImageCameraInfoTopicName>
           <pointCloudCutoff>0.4</pointCloudCutoff>
               <hackBaseline>0.07</hackBaseline>
               <distortionK1>0.0</distortionK1>
               <distortionK2>0.0</distortionK2>
               <distortionK3>0.0</distortionK3>
               <distortionT1>0.0</distortionT1>
               <distortionT2>0.0</distortionT2>
           <CxPrime>0.0</CxPrime>
           <Cx>0.0</Cx>
           <Cy>0.0</Cy>
           <focalLength>0</focalLength>
           <hackBaseline>0</hackBaseline>
         </plugin>
       </sensor>
     </gazebo>

       <gazebo reference="camera2">
       <sensor type="depth" name="realsense_R200">
         <always_on>true</always_on>
         <visualize>$(arg camera_visual)</visualize>
         <camera>
             <horizontal_fov>1.3439</horizontal_fov>
             <image>
                 <width>1920</width>
                 <height>1080</height>
                 <format>R8G8B8</format>
             </image>
             <depth_camera></depth_camera>
             <clip>
                 <near>0.03</near>
                 <far>100</far>
             </clip>
         </camera>
         <plugin name="camera_controller" filename="libgazebo_ros_openni_kinect.so">
           <baseline>0.2</baseline>
           <alwaysOn>true</alwaysOn>
           <updateRate>30.0</updateRate>
           <cameraName>camera2</cameraName>
           <frameName>camera_rgb_optical_frame</frameName>
           <imageTopicName>rgb/image_raw</imageTopicName>
           <depthImageTopicName>depth/image_raw</depthImageTopicName>
           <pointCloudTopicName>depth/points</pointCloudTopicName>
           <cameraInfoTopicName>rgb/camera_info</cameraInfoTopicName>
           <depthImageCameraInfoTopicName>depth/camera_info</depthImageCameraInfoTopicName>
           <pointCloudCutoff>0.4</pointCloudCutoff>
               <hackBaseline>0.07</hackBaseline>
               <distortionK1>0.0</distortionK1>
               <distortionK2>0.0</distortionK2>
               <distortionK3>0.0</distortionK3>
               <distortionT1>0.0</distortionT1>
               <distortionT2>0.0</distortionT2>
           <CxPrime>0.0</CxPrime>
           <Cx>0.0</Cx>
           <Cy>0.0</Cy>
           <focalLength>0</focalLength>
           <hackBaseline>0</hackBaseline>
         </plugin>
       </sensor>
     </gazebo>

   <gazebo reference="lidar">
       <material>Gazebo/FlatBlack</material>
       <sensor type="ray" name="lds_lfcd_sensor">
         <pose>0 0 0 0 0 0</pose>
         <visualize>$(arg laser_visual)</visualize>
         <update_rate>5</update_rate>
         <ray>
           <scan>
             <horizontal>
               <samples>360</samples>
               <resolution>1</resolution>
               <min_angle>0.0</min_angle>
               <max_angle>6.28319</max_angle>
             </horizontal>
           </scan>
           <range>
             <min>0.120</min>
             <max>3.5</max>
             <resolution>0.015</resolution>
           </range>
           <noise>
             <type>gaussian</type>
             <mean>0.0</mean>
             <stddev>0.01</stddev>
           </noise>
         </ray>
         <plugin name="gazebo_ros_lds_lfcd_controller" filename="libgazebo_ros_laser.so">
           <topicName>scan</topicName>
           <frameName>base_scan</frameName>
         </plugin>
       </sensor>
     </gazebo>

     <gazebo reference="imu">
       <sensor type="imu" name="imu">
         <always_on>true</always_on>
         <visualize>$(arg imu_visual)</visualize>
       </sensor>
       <material>Gazebo/Grey</material>
     </gazebo>
     <gazebo>
       <plugin name="imu_plugin" filename="libgazebo_ros_imu.so">
         <alwaysOn>true</alwaysOn>
         <bodyName>imu</bodyName>
         <frameName>imu</frameName>
         <topicName>imu_test</topicName>
         <serviceName>imu_service</serviceName>
         <gaussianNoise>0.01</gaussianNoise>
         <updateRate>200</updateRate>
       </plugin>
     </gazebo>

</robot>